<?xml version='1.0'?>
<sdf version='1.4'>
  <model name="enhanced_robot">
    <static>false</static>
    
    <!-- Main Chassis -->
    <link name='chassis'>
      <pose>0 0 0.15 0 0 0</pose>
      <inertial>
        <mass>1.5</mass>
        <inertia>
          <ixx>0.1</ixx>
          <ixy>0</ixy>
          <ixz>0</ixz>
          <iyy>0.1</iyy>
          <iyz>0</iyz>
          <izz>0.1</izz>
        </inertia>
      </inertial>
      
      <collision name='collision'>
        <geometry>
          <box>
            <size>0.4 0.2 0.1</size>
          </box>
        </geometry>
      </collision>

      <visual name='visual'>
        <geometry>
          <box>
            <size>0.4 0.2 0.1</size>
          </box>
        </geometry>
        <material>
          <ambient>0.7 0.3 0.1 1</ambient>
          <diffuse>0.8 0.4 0.2 1</diffuse>
          <specular>0.2 0.2 0.2 1</specular>
        </material>
      </visual>
      
      <!-- Add some texture to the chassis -->
      <visual name='chassis_details'>
        <pose>0.05 0 0.05 0 0 0</pose>
        <geometry>
          <box>
            <size>0.3 0.18 0.01</size>
          </box>
        </geometry>
        <material>
          <ambient>0.1 0.1 0.1 1</ambient>
          <diffuse>0.2 0.2 0.2 1</diffuse>
          <specular>0.3 0.3 0.3 1</specular>
        </material>
      </visual>
    </link>

    <!-- Upper Deck/Electronics Platform -->
    <link name='upper_deck'>
      <pose>0 0 0.21 0 0 0</pose>
      <inertial>
        <mass>0.3</mass>
        <inertia>
          <ixx>0.01</ixx>
          <ixy>0</ixy>
          <ixz>0</ixz>
          <iyy>0.01</iyy>
          <iyz>0</iyz>
          <izz>0.01</izz>
        </inertia>
      </inertial>
      
      <collision name='upper_deck_collision'>
        <geometry>
          <box>
            <size>0.3 0.18 0.02</size>
          </box>
        </geometry>
      </collision>

      <visual name='upper_deck_visual'>
        <geometry>
          <box>
            <size>0.3 0.18 0.02</size>
          </box>
        </geometry>
        <material>
          <ambient>0.05 0.3 0.4 1</ambient>
          <diffuse>0.1 0.5 0.6 1</diffuse>
          <specular>0.1 0.1 0.1 1</specular>
        </material>
      </visual>
      
      <!-- Add some circuit patterns on the deck -->
      <visual name='circuit_pattern'>
        <pose>0 0 0.011 0 0 0</pose>
        <geometry>
          <box>
            <size>0.25 0.15 0.001</size>
          </box>
        </geometry>
        <material>
          <ambient>0.1 0.8 0.1 1</ambient>
          <diffuse>0.1 0.9 0.1 1</diffuse>
          <emissive>0.05 0.2 0.05 1</emissive>
        </material>
      </visual>
    </link>

    <!-- Rear Left Wheel - More Realistic -->
    <link name="rear_left_wheel">
      <pose>0.1 0.13 0.1 0 1.5707 1.5707</pose>
      <inertial>
        <mass>0.3</mass>
        <inertia>
          <ixx>0.001</ixx>
          <ixy>0</ixy>
          <ixz>0</ixz>
          <iyy>0.001</iyy>
          <iyz>0</iyz>
          <izz>0.001</izz>
        </inertia>
      </inertial>
      
      <collision name="collision">
        <geometry>
          <cylinder>
            <radius>0.1</radius>
            <length>0.05</length>
          </cylinder>
        </geometry>
        <surface>
          <friction>
            <ode>
              <mu>100</mu>
              <mu2>50</mu2>
            </ode>
          </friction>
        </surface>
      </collision>

      <visual name="tire">
        <geometry>
          <cylinder>
            <radius>0.1</radius>
            <length>0.05</length>
          </cylinder>
        </geometry>
        <material>
          <ambient>0.1 0.1 0.1 1</ambient>
          <diffuse>0.1 0.1 0.1 1</diffuse>
          <specular>0.1 0.1 0.1 1</specular>
        </material>
      </visual>
      
      <!-- Wheel rim -->
      <visual name="rim">
        <pose>0 0 0 0 0 0</pose>
        <geometry>
          <cylinder>
            <radius>0.06</radius>
            <length>0.04</length>
          </cylinder>
        </geometry>
        <material>
          <ambient>0.7 0.7 0.7 1</ambient>
          <diffuse>0.8 0.8 0.8 1</diffuse>
          <specular>0.9 0.9 0.9 1</specular>
          <emissive>0.1 0.1 0.1 1</emissive>
        </material>
      </visual>
      
      <!-- Wheel spokes -->
      <visual name="spokes1">
        <pose>0 0 0 0 1.5707 0</pose>
        <geometry>
          <box>
            <size>0.02 0.12 0.02</size>
          </box>
        </geometry>
        <material>
          <ambient>0.7 0.7 0.7 1</ambient>
          <diffuse>0.8 0.8 0.8 1</diffuse>
        </material>
      </visual>
      
      <visual name="spokes2">
        <pose>0 0 0 0 1.5707 1.5707</pose>
        <geometry>
          <box>
            <size>0.02 0.12 0.02</size>
          </box>
        </geometry>
        <material>
          <ambient>0.7 0.7 0.7 1</ambient>
          <diffuse>0.8 0.8 0.8 1</diffuse>
        </material>
      </visual>
      
      <!-- Tire pattern -->
      <visual name="tread">
        <pose>0 0 0 0 0 0</pose>
        <geometry>
          <cylinder>
            <radius>0.101</radius>
            <length>0.04</length>
          </cylinder>
        </geometry>
        <material>
          <ambient>0.1 0.1 0.1 1</ambient>
          <diffuse>0.2 0.2 0.2 1</diffuse>
          <emissive>0 0 0 1</emissive>
        </material>
      </visual>
    </link>

    <!-- Rear Right Wheel - More Realistic -->
    <link name="rear_right_wheel">
      <pose>0.1 -0.13 0.1 0 1.5707 1.5707</pose>
      <inertial>
        <mass>0.3</mass>
        <inertia>
          <ixx>0.001</ixx>
          <ixy>0</ixy>
          <ixz>0</ixz>
          <iyy>0.001</iyy>
          <iyz>0</iyz>
          <izz>0.001</izz>
        </inertia>
      </inertial>
      
      <collision name="collision">
        <geometry>
          <cylinder>
            <radius>0.1</radius>
            <length>0.05</length>
          </cylinder>
        </geometry>
        <surface>
          <friction>
            <ode>
              <mu>100</mu>
              <mu2>50</mu2>
            </ode>
          </friction>
        </surface>
      </collision>

      <visual name="tire">
        <geometry>
          <cylinder>
            <radius>0.1</radius>
            <length>0.05</length>
          </cylinder>
        </geometry>
        <material>
          <ambient>0.1 0.1 0.1 1</ambient>
          <diffuse>0.1 0.1 0.1 1</diffuse>
          <specular>0.1 0.1 0.1 1</specular>
        </material>
      </visual>
      
      <!-- Wheel rim -->
      <visual name="rim">
        <pose>0 0 0 0 0 0</pose>
        <geometry>
          <cylinder>
            <radius>0.06</radius>
            <length>0.04</length>
          </cylinder>
        </geometry>
        <material>
          <ambient>0.7 0.7 0.7 1</ambient>
          <diffuse>0.8 0.8 0.8 1</diffuse>
          <specular>0.9 0.9 0.9 1</specular>
          <emissive>0.1 0.1 0.1 1</emissive>
        </material>
      </visual>
      
      <!-- Wheel spokes -->
      <visual name="spokes1">
        <pose>0 0 0 0 1.5707 0</pose>
        <geometry>
          <box>
            <size>0.02 0.12 0.02</size>
          </box>
        </geometry>
        <material>
          <ambient>0.7 0.7 0.7 1</ambient>
          <diffuse>0.8 0.8 0.8 1</diffuse>
        </material>
      </visual>
      
      <visual name="spokes2">
        <pose>0 0 0 0 1.5707 1.5707</pose>
        <geometry>
          <box>
            <size>0.02 0.12 0.02</size>
          </box>
        </geometry>
        <material>
          <ambient>0.7 0.7 0.7 1</ambient>
          <diffuse>0.8 0.8 0.8 1</diffuse>
        </material>
      </visual>
      
      <!-- Tire pattern -->
      <visual name="tread">
        <pose>0 0 0 0 0 0</pose>
        <geometry>
          <cylinder>
            <radius>0.101</radius>
            <length>0.04</length>
          </cylinder>
        </geometry>
        <material>
          <ambient>0.1 0.1 0.1 1</ambient>
          <diffuse>0.2 0.2 0.2 1</diffuse>
          <emissive>0 0 0 1</emissive>
        </material>
      </visual>
    </link>

    <!-- Front Left Wheel - More Realistic -->
    <link name="front_left_wheel">
      <pose>-0.15 0.13 0.1 0 1.5707 1.5707</pose>
      <inertial>
        <mass>0.3</mass>
        <inertia>
          <ixx>0.001</ixx>
          <ixy>0</ixy>
          <ixz>0</ixz>
          <iyy>0.001</iyy>
          <iyz>0</iyz>
          <izz>0.001</izz>
        </inertia>
      </inertial>
      
      <collision name="collision">
        <geometry>
          <cylinder>
            <radius>0.1</radius>
            <length>0.05</length>
          </cylinder>
        </geometry>
        <surface>
          <friction>
            <ode>
              <mu>100</mu>
              <mu2>50</mu2>
            </ode>
          </friction>
        </surface>
      </collision>

      <visual name="tire">
        <geometry>
          <cylinder>
            <radius>0.1</radius>
            <length>0.05</length>
          </cylinder>
        </geometry>
        <material>
          <ambient>0.1 0.1 0.1 1</ambient>
          <diffuse>0.1 0.1 0.1 1</diffuse>
          <specular>0.1 0.1 0.1 1</specular>
        </material>
      </visual>
      
      <!-- Wheel rim -->
      <visual name="rim">
        <pose>0 0 0 0 0 0</pose>
        <geometry>
          <cylinder>
            <radius>0.06</radius>
            <length>0.04</length>
          </cylinder>
        </geometry>
        <material>
          <ambient>0.7 0.7 0.7 1</ambient>
          <diffuse>0.8 0.8 0.8 1</diffuse>
          <specular>0.9 0.9 0.9 1</specular>
          <emissive>0.1 0.1 0.1 1</emissive>
        </material>
      </visual>
      
      <!-- Wheel spokes -->
      <visual name="spokes1">
        <pose>0 0 0 0 1.5707 0</pose>
        <geometry>
          <box>
            <size>0.02 0.12 0.02</size>
          </box>
        </geometry>
        <material>
          <ambient>0.7 0.7 0.7 1</ambient>
          <diffuse>0.8 0.8 0.8 1</diffuse>
        </material>
      </visual>
      
      <visual name="spokes2">
        <pose>0 0 0 0 1.5707 1.5707</pose>
        <geometry>
          <box>
            <size>0.02 0.12 0.02</size>
          </box>
        </geometry>
        <material>
          <ambient>0.7 0.7 0.7 1</ambient>
          <diffuse>0.8 0.8 0.8 1</diffuse>
        </material>
      </visual>
      
      <!-- Tire pattern -->
      <visual name="tread">
        <pose>0 0 0 0 0 0</pose>
        <geometry>
          <cylinder>
            <radius>0.101</radius>
            <length>0.04</length>
          </cylinder>
        </geometry>
        <material>
          <ambient>0.1 0.1 0.1 1</ambient>
          <diffuse>0.2 0.2 0.2 1</diffuse>
          <emissive>0 0 0 1</emissive>
        </material>
      </visual>
    </link>

    <!-- Front Right Wheel - More Realistic -->
    <link name="front_right_wheel">
      <pose>-0.15 -0.13 0.1 0 1.5707 1.5707</pose>
      <inertial>
        <mass>0.3</mass>
        <inertia>
          <ixx>0.001</ixx>
          <ixy>0</ixy>
          <ixz>0</ixz>
          <iyy>0.001</iyy>
          <iyz>0</iyz>
          <izz>0.001</izz>
        </inertia>
      </inertial>
      
      <collision name="collision">
        <geometry>
          <cylinder>
            <radius>0.1</radius>
            <length>0.05</length>
          </cylinder>
        </geometry>
        <surface>
          <friction>
            <ode>
              <mu>100</mu>
              <mu2>50</mu2>
            </ode>
          </friction>
        </surface>
      </collision>

      <visual name="tire">
        <geometry>
          <cylinder>
            <radius>0.1</radius>
            <length>0.05</length>
          </cylinder>
        </geometry>
        <material>
          <ambient>0.1 0.1 0.1 1</ambient>
          <diffuse>0.1 0.1 0.1 1</diffuse>
          <specular>0.1 0.1 0.1 1</specular>
        </material>
      </visual>
      
      <!-- Wheel rim -->
      <visual name="rim">
        <pose>0 0 0 0 0 0</pose>
        <geometry>
          <cylinder>
            <radius>0.06</radius>
            <length>0.04</length>
          </cylinder>
        </geometry>
        <material>
          <ambient>0.7 0.7 0.7 1</ambient>
          <diffuse>0.8 0.8 0.8 1</diffuse>
          <specular>0.9 0.9 0.9 1</specular>
          <emissive>0.1 0.1 0.1 1</emissive>
        </material>
      </visual>
      
      <!-- Wheel spokes -->
      <visual name="spokes1">
        <pose>0 0 0 0 1.5707 0</pose>
        <geometry>
          <box>
            <size>0.02 0.12 0.02</size>
          </box>
        </geometry>
        <material>
          <ambient>0.7 0.7 0.7 1</ambient>
          <diffuse>0.8 0.8 0.8 1</diffuse>
        </material>
      </visual>
      
      <visual name="spokes2">
        <pose>0 0 0 0 1.5707 1.5707</pose>
        <geometry>
          <box>
            <size>0.02 0.12 0.02</size>
          </box>
        </geometry>
        <material>
          <ambient>0.7 0.7 0.7 1</ambient>
          <diffuse>0.8 0.8 0.8 1</diffuse>
        </material>
      </visual>
      
      <!-- Tire pattern -->
      <visual name="tread">
        <pose>0 0 0 0 0 0</pose>
        <geometry>
          <cylinder>
            <radius>0.101</radius>
            <length>0.04</length>
          </cylinder>
        </geometry>
        <material>
          <ambient>0.1 0.1 0.1 1</ambient>
          <diffuse>0.2 0.2 0.2 1</diffuse>
          <emissive>0 0 0 1</emissive>
        </material>
      </visual>
    </link>

    <!-- Sensor Tower - Enhanced -->
    <link name="sensor_tower">
      <pose>0.05 0 0.25 0 0 0</pose>
      <inertial>
        <mass>0.1</mass>
        <inertia>
          <ixx>0.0005</ixx>
          <ixy>0</ixy>
          <ixz>0</ixz>
          <iyy>0.0005</iyy>
          <iyz>0</iyz>
          <izz>0.0005</izz>
        </inertia>
      </inertial>

      <collision name="sensor_collision">
        <geometry>
          <cylinder>
            <radius>0.03</radius>
            <length>0.1</length>
          </cylinder>
        </geometry>
      </collision>

      <visual name="sensor_visual">
        <geometry>
          <cylinder>
            <radius>0.03</radius>
            <length>0.1</length>
          </cylinder>
        </geometry>
        <material>
          <ambient>0.4 0.4 0.4 1</ambient>
          <diffuse>0.5 0.5 0.5 1</diffuse>
          <specular>0.6 0.6 0.6 1</specular>
        </material>
      </visual>
      
      <!-- Add some tech details -->
      <visual name="tower_details">
        <pose>0 0 0.02 0 0 0</pose>
        <geometry>
          <cylinder>
            <radius>0.035</radius>
            <length>0.01</length>
          </cylinder>
        </geometry>
        <material>
          <ambient>0.1 0.1 0.5 1</ambient>
          <diffuse>0.2 0.2 0.7 1</diffuse>
          <emissive>0.1 0.1 0.3 1</emissive>
        </material>
      </visual>

      <!-- LiDAR sensor -->
      <sensor name="lidar_sensor" type="ray">
        <pose>0 0 0.1 0 0 0</pose>
        <visualize>true</visualize>
        <update_rate>20</update_rate>
        <ray>
          <scan>
            <horizontal>
              <samples>360</samples>
              <resolution>1</resolution>
              <min_angle>-3.14</min_angle>
              <max_angle>3.14</max_angle>
            </horizontal>
          </scan>
          <range>
            <min>0.1</min>
            <max>10.0</max>
            <resolution>0.01</resolution>
          </range>
          <noise>
            <type>gaussian</type>
            <mean>0.0</mean>
            <stddev>0.01</stddev>
          </noise>
        </ray>

        <plugin name="gazebo_ros_laser_controller" filename="libgazebo_ros_laser.so">
          <topicName>/scan</topicName>
          <frameName>lidar_link</frameName>
        </plugin>
      </sensor>
    </link>

    <!-- Lidar Sensor - Enhanced -->
    <link name="lidar">
      <pose>0.05 0 0.33 0 0 0</pose>
      <inertial>
        <mass>0.1</mass>
        <inertia>
          <ixx>0.001</ixx>
          <ixy>0</ixy>
          <ixz>0</ixz>
          <iyy>0.001</iyy>
          <iyz>0</iyz>
          <izz>0.001</izz>
        </inertia>
      </inertial>
      
      <collision name="lidar_collision">
        <geometry>
          <cylinder>
            <radius>0.03</radius>
            <length>0.05</length>
          </cylinder>
        </geometry>
      </collision>

      <visual name="lidar_visual">
        <geometry>
          <cylinder>
            <radius>0.03</radius>
            <length>0.05</length>
          </cylinder>
        </geometry>
        <material>
          <ambient>0.1 0.1 0.1 1</ambient>
          <diffuse>0.2 0.2 0.2 1</diffuse>
          <specular>0.7 0.7 0.7 1</specular>
        </material>
      </visual>
      
      <!-- Add a spinning element to the lidar -->
      <visual name="lidar_spinner">
        <pose>0 0 0.025 0 0 0</pose>
        <geometry>
          <cylinder>
            <radius>0.035</radius>
            <length>0.01</length>
          </cylinder>
        </geometry>
        <material>
          <ambient>0.3 0.3 0.8 1</ambient>
          <diffuse>0.4 0.4 0.9 1</diffuse>
          <emissive>0.2 0.2 0.5 1</emissive>
        </material>
      </visual>
    </link>

    <!-- New: Add Exhaust Pipes on the back -->
    <link name="exhaust_pipe_left">
      <pose>-0.18 0.08 0.18 0 0.3 0</pose>
      <inertial>
        <mass>0.05</mass>
        <inertia>
          <ixx>0.0001</ixx>
          <ixy>0</ixy>
          <ixz>0</ixz>
          <iyy>0.0001</iyy>
          <iyz>0</iyz>
          <izz>0.0001</izz>
        </inertia>
      </inertial>
      
      <collision name="pipe_collision">
        <geometry>
          <cylinder>
            <radius>0.015</radius>
            <length>0.08</length>
          </cylinder>
        </geometry>
      </collision>
      
      <visual name="pipe_visual">
        <geometry>
          <cylinder>
            <radius>0.015</radius>
            <length>0.08</length>
          </cylinder>
        </geometry>
        <material>
          <ambient>0.5 0.5 0.5 1</ambient>
          <diffuse>0.7 0.7 0.7 1</diffuse>
          <specular>0.9 0.9 0.9 1</specular>
        </material>
      </visual>
      
      <!-- Pipe tip -->
      <visual name="pipe_tip">
        <pose>0 0 0.04 0 0 0</pose>
        <geometry>
          <cylinder>
            <radius>0.018</radius>
            <length>0.01</length>
          </cylinder>
        </geometry>
        <material>
          <ambient>0.3 0.3 0.3 1</ambient>
          <diffuse>0.4 0.4 0.4 1</diffuse>
          <specular>0.8 0.8 0.8 1</specular>
        </material>
      </visual>
    </link>
    
    <link name="exhaust_pipe_right">
      <pose>-0.18 -0.08 0.18 0 0.3 0</pose>
      <inertial>
        <mass>0.05</mass>
        <inertia>
          <ixx>0.0001</ixx>
          <ixy>0</ixy>
          <ixz>0</ixz>
          <iyy>0.0001</iyy>
          <iyz>0</iyz>
          <izz>0.0001</izz>
        </inertia>
      </inertial>
      
      <collision name="pipe_collision">
        <geometry>
          <cylinder>
            <radius>0.015</radius>
            <length>0.08</length>
          </cylinder>
        </geometry>
      </collision>
      
      <visual name="pipe_visual">
        <geometry>
          <cylinder>
            <radius>0.015</radius>
            <length>0.08</length>
          </cylinder>
        </geometry>
        <material>
          <ambient>0.5 0.5 0.5 1</ambient>
          <diffuse>0.7 0.7 0.7 1</diffuse>
          <specular>0.9 0.9 0.9 1</specular>
        </material>
      </visual>
      
      <!-- Pipe tip -->
      <visual name="pipe_tip">
        <pose>0 0 0.04 0 0 0</pose>
        <geometry>
          <cylinder>
            <radius>0.018</radius>
            <length>0.01</length>
          </cylinder>
        </geometry>
        <material>
          <ambient>0.3 0.3 0.3 1</ambient>
          <diffuse>0.4 0.4 0.4 1</diffuse>
          <specular>0.8 0.8 0.8 1</specular>
        </material>
      </visual>
    </link>

    <!-- Robot logo on top - Enhanced -->
    <link name="logo">
      <pose>0.05 0 0.36 0 0 0</pose>
      <visual name="logo_visual">
        <geometry>
          <box>
            <size>0.04 0.04 0.01</size>
          </box>
        </geometry>
        <material>
          <ambient>0 0.8 0.8 1</ambient>
          <diffuse>0 1 1 1</diffuse>
          <emissive>0 0.6 0.6 1</emissive>
        </material>
      </visual>
      
      <!-- Add a 3D logo element -->
      <visual name="logo_3d">
        <pose>0 0 0.01 0 0 0</pose>
        <geometry>
          <sphere>
            <radius>0.012</radius>
          </sphere>
        </geometry>
        <material>
          <ambient>0.8 0.2 0.8 1</ambient>
          <diffuse>1 0.3 1 1</diffuse>
          <emissive>0.5 0.1 0.5 1</emissive>
        </material>
      </visual>
    </link>

    <!-- Enhanced Front Lights -->
    <link name="front_light_left">
      <pose>0.19 0.08 0.13 0 0 0</pose>
      <visual name="light_visual">
        <geometry>
          <sphere>
            <radius>0.015</radius>
          </sphere>
        </geometry>
        <material>
          <ambient>1 1 0.5 1</ambient>
          <diffuse>1 1 0.5 1</diffuse>
          <emissive>1 1 0.5 1</emissive>
        </material>
      </visual>
      
      <!-- Light housing -->
      <visual name="light_housing">
        <pose>0 0 0 0 0 0</pose>
        <geometry>
          <cylinder>
            <radius>0.018</radius>
            <length>0.01</length>
          </cylinder>
        </geometry>
        <material>
          <ambient>0.7 0.7 0.7 1</ambient>
          <diffuse>0.8 0.8 0.8 1</diffuse>
          <specular>1 1 1 1</specular>
        </material>
      </visual>
      
      <!-- Light beam effect -->
      <visual name="light_beam">
        <pose>0.015 0 0 0 0 0</pose>
        <geometry>
          <cylinder>
            <radius>0.01</radius>
            <length>0.02</length>
          </cylinder>
        </geometry>
        <material>
          <ambient>1 1 0.7 0.3</ambient>
          <diffuse>1 1 0.7 0.3</diffuse>
          <emissive>1 1 0.7 0.3</emissive>
        </material>
      </visual>
    </link>

    <link name="front_light_right">
      <pose>0.19 -0.08 0.13 0 0 0</pose>
      <visual name="light_visual">
        <geometry>
          <sphere>
            <radius>0.015</radius>
          </sphere>
        </geometry>
        <material>
          <ambient>1 1 0.5 1</ambient>
          <diffuse>1 1 0.5 1</diffuse>
          <emissive>1 1 0.5 1</emissive>
        </material>
      </visual>
      
      <!-- Light housing -->
      <visual name="light_housing">
        <pose>0 0 0 0 0 0</pose>
        <geometry>
          <cylinder>
            <radius>0.018</radius>
            <length>0.01</length>
          </cylinder>
        </geometry>
        <material>
          <ambient>0.7 0.7 0.7 1</ambient>
          <diffuse>0.8 0.8 0.8 1</diffuse>
          <specular>1 1 1 1</specular>
        </material>
      </visual>
      
      <!-- Light beam effect -->
      <visual name="light_beam">
        <pose>0.015 0 0 0 0 0</pose>
        <geometry>
          <cylinder>
            <radius>0.01</radius>
            <length>0.02</length>
          </cylinder>
        </geometry>
        <material>
          <ambient>1 1 0.7 0.3</ambient>
          <diffuse>1 1 0.7 0.3</diffuse>
          <emissive>1 1 0.7 0.3</emissive>
        </material>
      </visual>
    </link>
    
    <!-- Add additional headlights -->
    <link name="main_headlight_left">
      <pose>0.2 0.05 0.17 0 0 0</pose>
      <visual name="headlight_visual">
        <geometry>
          <cylinder>
            <radius>0.02</radius>
            <length>0.01</length>
          </cylinder>
        </geometry>
        <material>
          <ambient>1 1 0.8 1</ambient>
          <diffuse>1 1 0.8 1</diffuse>
          <emissive>1 1 0.8 1</emissive>
        </material>
      </visual>
      
      <!-- Headlight casing -->
      <visual name="headlight_casing">
        <pose>0 0 -0.005 0 0 0</pose>
        <geometry>
          <cylinder>
            <radius>0.025</radius>
            <length>0.01</length>
          </cylinder>
        </geometry>
        <material>
          <ambient>0.8 0.8 0.8 1</ambient>
          <diffuse>0.9 0.9 0.9 1</diffuse>
          <specular>1 1 1 1</specular>
        </material>
      </visual>
    </link>
    
    <link name="main_headlight_right">
      <pose>0.2 -0.05 0.17 0 0 0</pose>
      <visual name="headlight_visual">
        <geometry>
          <cylinder>
            <radius>0.02</radius>
            <length>0.01</length>
          </cylinder>
        </geometry>
        <material>
          <ambient>1 1 0.8 1</ambient>
          <diffuse>1 1 0.8 1</diffuse>
          <emissive>1 1 0.8 1</emissive>
        </material>
      </visual>
      
      <!-- Headlight casing -->
      <visual name="headlight_casing">
        <pose>0 0 -0.005 0 0 0</pose>
        <geometry>
          <cylinder>
            <radius>0.025</radius>
            <length>0.01</length>
          </cylinder>
        </geometry>
        <material>
          <ambient>0.8 0.8 0.8 1</ambient>
          <diffuse>0.9 0.9 0.9 1</diffuse>
          <specular>1 1 1 1</specular>
        </material>
      </visual>
    </link>
    
    <!-- Add decorative bumper -->
    <link name="front_bumper">
      <pose>0.2 0 0.1 0 0 0</pose>
      <visual name="bumper_visual">
        <geometry>
          <box>
            <size>0.03 0.18 0.05</size>
          </box>
        </geometry>
        <material>
          <ambient>0.4 0.4 0.4 1</ambient>
          <diffuse>0.6 0.6 0.6 1</diffuse>
          <specular>0.8 0.8 0.8 1</specular>
        </material>
      </visual>
      
      <!-- Bumper detail -->
      <visual name="bumper_detail">
        <pose>0.01 0 0 0 0 0</pose>
        <geometry>
          <box>
            <size>0.01 0.17 0.04</size>
          </box>
        </geometry>
        <material>
          <ambient>0.1 0.1 0.1 1</ambient>
          <diffuse>0.2 0.2 0.2 1</diffuse>
        </material>
      </visual>
    </link>
    
    <!-- Add rear taillights -->
    <link name="taillight_left">
      <pose>-0.2 0.08 0.13 0 0 0</pose>
      <visual name="taillight_visual">
        <geometry>
          <sphere>
            <radius>0.012</radius>
          </sphere>
        </geometry>
        <material>
          <ambient>0.8 0.1 0.1 1</ambient>
          <diffuse>1 0.2 0.2 1</diffuse>
          <emissive>0.8 0.2 0.2 1</emissive>
        </material>
      </visual>
      
      <!-- Light housing -->
      <visual name="light_housing">
        <pose>0 0 0 0 0 0</pose>
        <geometry>
          <cylinder>
            <radius>0.015</radius>
            <length>0.008</length>
          </cylinder>
        </geometry>
        <material>
          <ambient>0.3 0.3 0.3 1</ambient>
          <diffuse>0.4 0.4 0.4 1</diffuse>
          <specular>0.7 0.7 0.7 1</specular>
        </material>
      </visual>
    </link>
    
    <link name="taillight_right">
      <pose>-0.2 -0.08 0.13 0 0 0</pose>
      <visual name="taillight_visual">
        <geometry>
          <sphere>
            <radius>0.012</radius>
          </sphere>
        </geometry>
        <material>
          <ambient>0.8 0.1 0.1 1</ambient>
          <diffuse>1 0.2 0.2 1</diffuse>
          <emissive>0.8 0.2 0.2 1</emissive>
        </material>
      </visual>
      
      <!-- Light housing -->
      <visual name="light_housing">
        <pose>0 0 0 0 0 0</pose>
        <geometry>
          <cylinder>
            <radius>0.015</radius>
            <length>0.008</length>
          </cylinder>
        </geometry>
        <material>
          <ambient>0.3 0.3 0.3 1</ambient>
          <diffuse>0.4 0.4 0.4 1</diffuse>
          <specular>0.7 0.7 0.7 1</specular>
        </material>
      </visual>
    </link>
    
    <!-- Add small antennas -->
    <link name="antenna_left">
      <pose>0.05 0.09 0.35 0 0 0</pose>
      <visual name="antenna_visual">
        <geometry>
          <cylinder>
            <radius>0.002</radius>
            <length>0.08</length>
          </cylinder>
        </geometry>
        <material>
          <ambient>0.1 0.1 0.1 1</ambient>
          <diffuse>0.2 0.2 0.2 1</diffuse>
        </material>
      </visual>
      
      <!-- Antenna tip -->
      <visual name="antenna_tip">
        <pose>0 0 0.045 0 0 0</pose>
        <geometry>
          <sphere>
            <radius>0.004</radius>
          </sphere>
        </geometry>
        <material>
          <ambient>0.9 0.1 0.1 1</ambient>
          <diffuse>1 0.2 0.2 1</diffuse>
          <emissive>0.5 0.1 0.1 1</emissive>
        </material>
      </visual>
    </link>
    
    <link name="antenna_right">
      <pose>0.05 -0.09 0.35 0 0 0</pose>
      <visual name="antenna_visual">
        <geometry>
          <cylinder>
            <radius>0.002</radius>
            <length>0.08</length>
          </cylinder>
        </geometry>
        <material>
          <ambient>0.1 0.1 0.1 1</ambient>
          <diffuse>0.2 0.2 0.2 1</diffuse>
        </material>
      </visual>
      
      <!-- Antenna tip -->
      <visual name="antenna_tip">
        <pose>0 0 0.045 0 0 0</pose>
        <geometry>
          <sphere>
            <radius>0.004</radius>
          </sphere>
        </geometry>
        <material>
          <ambient>0.1 0.9 0.1 1</ambient>
          <diffuse>0.2 1 0.2 1</diffuse>
          <emissive>0.1 0.5 0.1 1</emissive>
        </material>
      </visual>
    </link>

    <!-- JOINTS -->
    
    <!-- Rear Left Wheel Joint -->
    <joint type="revolute" name="rear_left_wheel_hinge">
      <pose>0 0 0 0 0 0</pose>
      <child>rear_left_wheel</child>
      <parent>chassis</parent>
      <axis>
        <xyz>0 1 0</xyz>
        <dynamics>
          <damping>0.1</damping>
          <friction>0.1</friction>
        </dynamics>
      </axis>
    </joint>

    <!-- Rear Right Wheel Joint -->
    <joint type="revolute" name="rear_right_wheel_hinge">
      <pose>0 0 0 0 0 0</pose>
      <child>rear_right_wheel</child>
      <parent>chassis</parent>
      <axis>
        <xyz>0 1 0</xyz>
        <dynamics>
          <damping>0.1</damping>
          <friction>0.1</friction>
        </dynamics>
      </axis>
    </joint>
    
    <!-- Front Left Wheel Joint -->
    <joint type="revolute" name="front_left_wheel_hinge">
      <pose>0 0 0 0 0 0</pose>
      <child>front_left_wheel</child>
      <parent>chassis</parent>
      <axis>
        <xyz>0 1 0</xyz>
        <dynamics>
          <damping>0.1</damping>
          <friction>0.1</friction>
        </dynamics>
      </axis>
    </joint>

    <!-- Front Right Wheel Joint -->
    <joint type="revolute" name="front_right_wheel_hinge">
      <pose>0 0 0 0 0 0</pose>
      <child>front_right_wheel</child>
      <parent>chassis</parent>
      <axis>
        <xyz>0 1 0</xyz>
        <dynamics>
          <damping>0.1</damping>
          <friction>0.1</friction>
        </dynamics>
      </axis>
    </joint>

    <!-- Upper Deck Joint -->
    <joint type="fixed" name="upper_deck_joint">
      <parent>chassis</parent>
      <child>upper_deck</child>
    </joint>

    <!-- Sensor Tower Joint -->
    <joint type="fixed" name="sensor_tower_joint">
      <parent>upper_deck</parent>
      <child>sensor_tower</child>
    </joint>

    <!-- Lidar Joint -->
    <joint type="fixed" name="lidar_joint">
      <parent>sensor_tower</parent>
      <child>lidar</child>
    </joint>

    <!-- Logo Joint -->
    <joint type="fixed" name="logo_joint">
      <parent>lidar</parent>
      <child>logo</child>
    </joint>

    <!-- Front Lights Joints -->
    <joint type="fixed" name="front_light_left_joint">
      <parent>chassis</parent>
      <child>front_light_left</child>
    </joint>

    <joint type="fixed" name="front_light_right_joint">
      <parent>chassis</parent>
      <child>front_light_right</child>
    </joint>
    
    <!-- Exhaust Pipes Joints -->
    <joint type="fixed" name="exhaust_pipe_left_joint">
      <parent>chassis</parent>
      <child>exhaust_pipe_left</child>
    </joint>
    
    <joint type="fixed" name="exhaust_pipe_right_joint">
      <parent>chassis</parent>
      <child>exhaust_pipe_right</child>
    </joint>
    
    <!-- Additional headlights joints -->
    <joint type="fixed" name="main_headlight_left_joint">
      <parent>chassis</parent>
      <child>main_headlight_left</child>
    </joint>
    
    <joint type="fixed" name="main_headlight_right_joint">
      <parent>chassis</parent>
      <child>main_headlight_right</child>
    </joint>
    
    <!-- Bumper joint -->
    <joint type="fixed" name="front_bumper_joint">
      <parent>chassis</parent>
      <child>front_bumper</child>
    </joint>
    
    <!-- Taillights joints -->
    <joint type="fixed" name="taillight_left_joint">
      <parent>chassis</parent>
      <child>taillight_left</child>
    </joint>
    
    <joint type="fixed" name="taillight_right_joint">
      <parent>chassis</parent>
      <child>taillight_right</child>
    </joint>
    
    <!-- Antenna joints -->
    <joint type="fixed" name="antenna_left_joint">
      <parent>upper_deck</parent>
      <child>antenna_left</child>
    </joint>
    
    <joint type="fixed" name="antenna_right_joint">
      <parent>upper_deck</parent>
      <child>antenna_right</child>
    </joint>

    <!-- Adding a differential drive plugin for 4 wheels -->
    <plugin name="four_wheel_drive_controller" filename="libgazebo_ros_diff_drive.so">
      <alwaysOn>true</alwaysOn>
      <updateRate>20</updateRate>
      <leftJoint>rear_left_wheel_hinge</leftJoint>
      <rightJoint>rear_right_wheel_hinge</rightJoint>
      <wheelSeparation>0.26</wheelSeparation>
      <wheelDiameter>0.2</wheelDiameter>
      <torque>20</torque>
      <commandTopic>cmd_vel</commandTopic>
      <odometryTopic>odom</odometryTopic>
      <odometryFrame>odom</odometryFrame>
      <robotBaseFrame>chassis</robotBaseFrame>
    </plugin>

    <!-- Optional: Additional controller for front wheels -->
    <plugin name="front_wheel_drive" filename="libgazebo_ros_diff_drive.so">
      <alwaysOn>true</alwaysOn>
      <updateRate>20</updateRate>
      <leftJoint>front_left_wheel_hinge</leftJoint>
      <rightJoint>front_right_wheel_hinge</rightJoint>
      <wheelSeparation>0.26</wheelSeparation>
      <wheelDiameter>0.2</wheelDiameter>
      <torque>20</torque>
      <commandTopic>front_cmd_vel</commandTopic>
      <odometryFrame>odom</odometryFrame>
      <robotBaseFrame>chassis</robotBaseFrame>
      <publishOdometry>false</publishOdometry>
    </plugin>
  </model>
</sdf>
